Workbook

Sheet Schneider Electric
I7: FINANCIAL ANALYSIS & STRATEGIC RECOMMENDATIONS FY2021 - FY2025

Sheet Income Statement
M2: Income Statement | AF2: Income Statement for year 1 using by function (€m)
N3: Q1 2026 | O3: Trend | P3: Common-size | Q3: FY2025 (€m) | R3: trend | S3: common-size | T3: FY2024 (€m) | U3: trend | V3: common-size | W3: FY2023 (€m) | X3: trend | Y3: common-size | Z3: FY2022 (€m) | AA3: trend | AB3: common-size | AC3: FY2021 (€m) | AD3: common-size | AF3: Items | AG3: Q1 2026 | AH3: 2025 | AI3: 2024 | AJ3: 2023 | AK3: 2022 | AL3: 2021
M4: Revenue | Q4: 40152 | R4: =Q4/AC4-1 -> 0.38910223 | S4: =Q4/$Q$4 -> 1 | T4: 38153 | U4: =T4/AC4-1 -> 0.31994465 | V4: =T4/$T$4 -> 1 | W4: 35902 | X4: =W4/AC4-1 -> 0.24206885 | Y4: =W4/$W$4 -> 1 | Z4: 34176 | AA4: =Z4/AC4-1 -> 0.18235599 | AB4: =Z4/$Z$4 -> 1 | AC4: 28905 | AD4: =AC4/$AC$4 -> 1 | AF4: Net Sales | AH4: =Q4 -> 40152 | AI4: =T4 -> 38153 | AJ4: =W4 -> 35902 | AK4: =Z4 -> 34176 | AL4: =AC4 -> 28905
M5: Cost of sales | Q5: -23257 | R5: =Q5/AC5-1 -> 0.36308756 | S5: =Q5/$Q$4 -> -0.57922395 | T5: -21885 | U5: =T5/AC5-1 -> 0.28267495 | V5: =T5/$T$4 -> -0.57361151 | W5: -20890 | X5: =W5/AC5-1 -> 0.22435822 | Y5: =W5/$W$4 -> -0.58186173 | Z5: -20300 | AA5: =Z5/AC5-1 -> 0.18977846 | AB5: =Z5/$Z$4 -> -0.59398408 | AC5: -17062 | AD5: =AC5/$AC$4 -> -0.5902785 | AF5: - Cost of goods sold (COGS) | AH5: =Q5+Q14+Q10+Q11 -> -24078 | AI5: =T5+T14+T10+T11 -> -22519 | AJ5: =W5+W14+W10+W11 -> -21369 | AK5: =Z5+Z14+Z10+Z11 -> -21384 | AL5: =AC5+AC14+AC10+AC11 -> -17718
M6: Gross profit | Q6: 16895 | R6: =Q6/AC6-1 -> 0.4265811 | S6: =Q6/$Q$4 -> 0.42077605 | T6: 16268 | U6: =T6/AC6-1 -> 0.37363844 | V6: =T6/$T$4 -> 0.42638849 | W6: 15012 | X6: =W6/AC6-1 -> 0.26758423 | Y6: =W6/$W$4 -> 0.41813827 | Z6: 13876 | AA6: =Z6/AC6-1 -> 0.17166259 | AB6: =Z6/$Z$4 -> 0.40601592 | AC6: 11843 | AD6: =AC6/$AC$4 -> 0.4097215 | AF6: Gross Margin | AH6: =AH4+AH5 -> 16074 | AI6: =AI4+AI5 -> 15634 | AJ6: =AJ4+AJ5 -> 14533 | AK6: =AK4+AK5 -> 12792 | AL6: =AL4+AL5 -> 11187
M7: Research and development | Q7: -1365 | R7: =Q7/AC7-1 -> 0.59649123 | S7: =Q7/$Q$4 -> -0.033995816 | T7: -1308 | U7: =T7/AC7-1 -> 0.52982456 | V7: =T7/$T$4 -> -0.034283018 | W7: -1168 | X7: =W7/AC7-1 -> 0.36608187 | Y7: =W7/$W$4 -> -0.032533007 | Z7: -1040 | AA7: =Z7/AC7-1 -> 0.21637427 | AB7: =Z7/$Z$4 -> -0.030430712 | AC7: -855 | AD7: =AC7/$AC$4 -> -0.029579657 | AF7: ="- Selling and marketing costs" -> - Selling and marketing costs | AH7: =Q8 -> -8010 | AI7: =T8 -> -7877 | AJ7: =W8 -> -7432 | AK7: =Z8 -> -6819 | AL7: =AC8 -> -6001
M8: Selling, general and administrative expenses | Q8: -8010 | R8: =Q8/AC8-1 -> 0.33477754 | S8: =Q8/$Q$4 -> -0.19949193 | T8: -7877 | U8: =T8/AC8-1 -> 0.31261456 | V8: =T8/$T$4 -> -0.20645821 | W8: -7432 | X8: =W8/AC8-1 -> 0.23846026 | Y8: =W8/$W$4 -> -0.20700797 | Z8: -6819 | AA8: =Z8/AC8-1 -> 0.13631061 | AB8: =Z8/$Z$4 -> -0.19952598 | AC8: -6001 | AD8: =AC8/$AC$4 -> -0.20761114 | AF8: - General and administrative costs (G&A) | AH8: =Q7 -> -1365 | AI8: =T7 -> -1308 | AJ8: =W7 -> -1168 | AK8: =Z7 -> -1040 | AL8: =AC7 -> -855
M9: Adjusted EBITA | Q9: 7520 | R9: =Q9/AC9-1 -> 0.50792059 | S9: =Q9/$Q$4 -> 0.1872883 | T9: 7083 | U9: =T9/AC9-1 -> 0.42029276 | V9: =T9/$T$4 -> 0.18564726 | W9: 6412 | X9: =W9/AC9-1 -> 0.28574293 | Y9: =W9/$W$4 -> 0.17859729 | Z9: 6017 | AA9: =Z9/AC9-1 -> 0.206537 | AB9: =Z9/$Z$4 -> 0.17605922 | AC9: 4987 | AD9: =AC9/$AC$4 -> 0.1725307 | AF9: EBIT | AH9: =AH6+AH7+AH8 -> 6699 | AI9: =AI6+AI7+AI8 -> 6449 | AJ9: =AJ6+AJ7+AJ8 -> 5933 | AK9: =AK6+AK7+AK8 -> 4933 | AL9: =AL6+AL7+AL8 -> 4331
M10: Other operating income and expenses | Q10: -77 | R10: =Q10/AC10-1 -> 2.6666667 | S10: =Q10/$Q$4 -> -0.0019177127 | T10: -87 | U10: =T10/AC10-1 -> 3.1428571 | V10: =T10/$T$4 -> -0.0022802925 | W10: 98 | X10: =W10/AC10-1 -> -5.6666667 | Y10: =W10/$W$4 -> 0.0027296529 | Z10: -433 | AA10: =Z10/AC10-1 -> 19.619048 | AB10: =Z10/$Z$4 -> -0.01266971 | AC10: -21 | AD10: =AC10/$AC$4 -> -0.0007265179 | AF10: ="- Financial expense net of Financial income" -> - Financial expense net of Financial income | AH10: =Q18+Q19 -> -519 | AI10: =T18+T19 -> -409 | AJ10: =W18+W19 -> -530 | AK10: =Z18+Z19 -> -215 | AL10: =AC18+AC19 -> -176
M11: Restructuring charges | Q11: -287 | R11: =Q11/AC11-1 -> 0.27555556 | S11: =Q11/$Q$4 -> -0.0071478382 | T11: -141 | U11: =T11/AC11-1 -> -0.37333333 | V11: =T11/$T$4 -> -0.0036956465 | W11: -147 | X11: =W11/AC11-1 -> -0.34666667 | Y11: =W11/$W$4 -> -0.0040944794 | Z11: -227 | AA11: =Z11/AC11-1 -> 0.0088888889 | AB11: =Z11/$Z$4 -> -0.006642088 | AC11: -225 | AD11: =AC11/$AC$4 -> -0.0077841204 | AF11: EBT/PBT | AH11: =AH9+AH10 -> 6180 | AI11: =AI9+AI10 -> 6040 | AJ11: =AJ9+AJ10 -> 5403 | AK11: =AK9+AK10 -> 4718 | AL11: =AL9+AL10 -> 4155
M12: EBITA | Q12: 7156 | R12: =Q12/AC12-1 -> 0.50938621 | S12: =Q12/$Q$4 -> 0.17822275 | T12: 6855 | U12: =T12/AC12-1 -> 0.44589749 | V12: =T12/$T$4 -> 0.17967132 | W12: 6363 | X12: =W12/AC12-1 -> 0.34212192 | Y12: =W12/$W$4 -> 0.17723247 | Z12: 5357 | AA12: =Z12/AC12-1 -> 0.12993039 | AB12: =Z12/$Z$4 -> 0.15674743 | AC12: 4741 | AD12: =AC12/$AC$4 -> 0.16402007 | AF12: - Corporate Income Tax | AH12: =Q22+Q23+Q24 -> -1829 | AI12: =T22+T23+T24 -> -1601 | AJ12: =W22+W23 -> -1234 | AK12: =Z22+Z23 -> -1182 | AL12: =AC22+AC23 -> -882
M13: EBITDA (restated) | N13: =N12+'Cash Flow Statement'!P6 -> #VALUE! | O13: =N13/AC13-1 -> #VALUE! | P13: =N13/N4 -> #VALUE! | Q13: =Q12+'Cash Flow Statement'!S6 -> 8027 | R13: =Q13/AC13-1 -> 0.47854117 | S13: =Q13/Q4 -> 0.19991532 | T13: =T12+'Cash Flow Statement'!U6 -> 7677 | U13: =T13/AC13-1 -> 0.41407257 | V13: =T13/T4 -> 0.20121616 | W13: =W12+'Cash Flow Statement'!W6 -> 7080 | X13: =W13/AC13-1 -> 0.30410757 | Y13: =W13/W4 -> 0.1972035 | Z13: =Z12+'Cash Flow Statement'!Y6 -> 6089 | AA13: =Z13/AC13-1 -> 0.12156935 | AB13: =Z13/Z4 -> 0.17816596 | AC13: =AC12+'Cash Flow Statement'!AA6 -> 5429 | AD13: =AC13/AC4 -> 0.18782218 | AF13: Net Income / Net Profit | AH13: =AH11+AH12 -> 4351 | AI13: =AI11+AI12 -> 4439 | AJ13: =AJ11+AJ12 -> 4169 | AK13: =AK11+AK12 -> 3536 | AL13: =AL11+AL12 -> 3273
M14: Amortization of acquisition-related intangibles | Q14: -457 | R14: =Q14/AC14-1 -> 0.11463415 | S14: =Q14/$Q$4 -> -0.011381749 | T14: -406 | U14: =T14/AC14-1 -> -0.0097560976 | V14: =T14/$T$4 -> -0.010641365 | W14: -430 | X14: =W14/AC14-1 -> 0.048780488 | Y14: =W14/$W$4 -> -0.011977049 | Z14: -424 | AA14: =Z14/AC14-1 -> 0.034146341 | AB14: =Z14/$Z$4 -> -0.012406367 | AC14: -410 | AD14: =AC14/$AC$4 -> -0.014184397
M15: Operating income (EBIT) | Q15: 6699 | R15: =Q15/AC15-1 -> 0.54675595 | S15: =Q15/$Q$4 -> 0.166841 | T15: 6449 | U15: =T15/AC15-1 -> 0.48903256 | V15: =T15/$T$4 -> 0.16902996 | W15: 5933 | X15: =W15/AC15-1 -> 0.36989148 | Y15: =W15/$W$4 -> 0.16525542 | Z15: 4933 | AA15: =Z15/AC15-1 -> 0.13899792 | AB15: =Z15/$Z$4 -> 0.14434106 | AC15: 4331 | AD15: =AC15/$AC$4 -> 0.14983567
M16: Income from cash and cash equivalents | Q16: 152 | R16: =Q16/AC16-1 -> 37 | S16: =Q16/$Q$4 -> 0.0037856147 | T16: 174 | U16: =T16/AC16-1 -> 42.5 | V16: =T16/$T$4 -> 0.004560585 | W16: 79 | X16: =W16/AC16-1 -> 18.75 | Y16: =W16/$W$4 -> 0.0022004345 | Z16: 24 | AA16: =Z16/AC16-1 -> 5 | AB16: =Z16/$Z$4 -> 0.00070224719 | AC16: 4 | AD16: =AC16/$AC$4 -> 0.00013838436
M17: Gross cost of financial debt | Q17: -473 | R17: =Q17/AC17-1 -> 3.7777778 | S17: =Q17/$Q$4 -> -0.011780235 | T17: -435 | U17: =T17/AC17-1 -> 3.3939394 | V17: =T17/$T$4 -> -0.011401463 | W17: -387 | X17: =W17/AC17-1 -> 2.9090909 | Y17: =W17/$W$4 -> -0.010779344 | Z17: -130 | AA17: =Z17/AC17-1 -> 0.31313131 | AB17: =Z17/$Z$4 -> -0.003803839 | AC17: -99 | AD17: =AC17/$AC$4 -> -0.003425013
M18: Net cost of financial debt | Q18: -321 | R18: =Q18/AC18-1 -> 2.3789474 | S18: =Q18/$Q$4 -> -0.0079946204 | T18: -261 | U18: =T18/AC18-1 -> 1.7473684 | V18: =T18/$T$4 -> -0.0068408775 | W18: -308 | X18: =W18/AC18-1 -> 2.2421053 | Y18: =W18/$W$4 -> -0.0085789093 | Z18: -106 | AA18: =Z18/AC18-1 -> 0.11578947 | AB18: =Z18/$Z$4 -> -0.0031015918 | AC18: -95 | AD18: =AC18/$AC$4 -> -0.0032866286
M19: Other financial income and expenses | Q19: -198 | R19: =Q19/AC19-1 -> 1.4444444 | S19: =Q19/$Q$4 -> -0.0049312612 | T19: -148 | U19: =T19/AC19-1 -> 0.82716049 | V19: =T19/$T$4 -> -0.0038791183 | W19: -222 | X19: =W19/AC19-1 -> 1.7407407 | Y19: =W19/$W$4 -> -0.0061834995 | Z19: -109 | AA19: =Z19/AC19-1 -> 0.34567901 | AB19: =Z19/$Z$4 -> -0.0031893727 | AC19: -81 | AD19: =AC19/$AC$4 -> -0.0028022833
M20: Net financial result | Q20: -519 | R20: =Q20/AC20-1 -> 1.9488636 | S20: =Q20/$Q$4 -> -0.012925882 | T20: -409 | U20: =T20/AC20-1 -> 1.3238636 | V20: =T20/$T$4 -> -0.010719996 | W20: -530 | X20: =W20/AC20-1 -> 2.0113636 | Y20: =W20/$W$4 -> -0.014762409 | Z20: -215 | AA20: =Z20/AC20-1 -> 0.22159091 | AB20: =Z20/$Z$4 -> -0.0062909644 | AC20: -176 | AD20: =AC20/$AC$4 -> -0.006088912
M21: Income before taxes | Q21: 6180 | R21: =Q21/AC21-1 -> 0.48736462 | S21: =Q21/$Q$4 -> 0.15391512 | T21: 6040 | U21: =T21/AC21-1 -> 0.45367028 | V21: =T21/$T$4 -> 0.15830996 | W21: 5403 | X21: =W21/AC21-1 -> 0.30036101 | Y21: =W21/$W$4 -> 0.15049301 | Z21: 4718 | AA21: =Z21/AC21-1 -> 0.1354994 | AB21: =Z21/$Z$4 -> 0.13805009 | AC21: 4155 | AD21: =AC21/$AC$4 -> 0.14374676
M22: Income tax expense | Q22: -1455 | R22: =Q22/AC22-1 -> 0.50621118 | S22: =Q22/$Q$4 -> -0.036237298 | T22: -1398 | U22: =T22/AC22-1 -> 0.44720497 | V22: =T22/$T$4 -> -0.036641942 | W22: -1285 | X22: =W22/AC22-1 -> 0.33022774 | Y22: =W22/$W$4 -> -0.035791878 | Z22: -1211 | AA22: =Z22/AC22-1 -> 0.25362319 | AB22: =Z22/$Z$4 -> -0.035434223 | AC22: -966 | AD22: =AC22/$AC$4 -> -0.033419824
M23: Share of profit of equity-accounted investments | Q23: 14 | R23: =Q23/AC23-1 -> -0.83333333 | S23: =Q23/$Q$4 -> 0.00034867503 | T23: 17 | U23: =T23/AC23-1 -> -0.79761905 | V23: =T23/$T$4 -> 0.0004455744 | W23: 51 | X23: =W23/AC23-1 -> -0.39285714 | Y23: =W23/$W$4 -> 0.0014205337 | Z23: 29 | AA23: =Z23/AC23-1 -> -0.6547619 | AB23: =Z23/$Z$4 -> 0.00084854869 | AC23: 84 | AD23: =AC23/$AC$4 -> 0.0029060716
M24: Impairment of investments in associates and joint ventures | Q24: -388 | R24: =Q24/T24-1 -> 0.76363636 | S24: =Q24/$Q$4 -> -0.0096632795 | T24: -220 | V24: =T24/$T$4 -> -0.0057662569 | W24: - | Z24: - | AC24: -
M25: Net income | Q25: 4351 | R25: =Q25/AC25-1 -> 0.32936144 | S25: =Q25/$Q$4 -> 0.10836322 | T25: 4439 | U25: =T25/AC25-1 -> 0.35624809 | V25: =T25/$T$4 -> 0.11634734 | W25: 4169 | X25: =W25/AC25-1 -> 0.27375496 | Y25: =W25/$W$4 -> 0.11612166 | Z25: 3536 | AA25: =Z25/AC25-1 -> 0.080354415 | AB25: =Z25/$Z$4 -> 0.10346442 | AC25: 3273 | AD25: =AC25/$AC$4 -> 0.113233
M26: of which attributable to shareholders of the parent | Q26: 4163 | R26: =Q26/AC26-1 -> 0.29931336 | S26: =Q26/$Q$4 -> 0.10368101 | T26: 4269 | U26: =T26/AC26-1 -> 0.332397 | V26: =T26/$T$4 -> 0.11189159 | W26: 4003 | X26: =W26/AC26-1 -> 0.24937578 | Y26: =W26/$W$4 -> 0.11149797 | Z26: 3477 | AA26: =Z26/AC26-1 -> 0.085205993 | AB26: =Z26/$Z$4 -> 0.10173806 | AC26: 3204 | AD26: =AC26/$AC$4 -> 0.11084587
M27: of which attributable to non-controlling interests | Q27: 188 | R27: =Q27/AC27-1 -> 1.7246377 | S27: =Q27/$Q$4 -> 0.0046822076 | T27: 170 | U27: =T27/AC27-1 -> 1.4637681 | V27: =T27/$T$4 -> 0.004455744 | W27: 166 | X27: =W27/AC27-1 -> 1.4057971 | Y27: =W27/$W$4 -> 0.0046236978 | Z27: 59 | AA27: =Z27/AC27-1 -> -0.14492754 | AB27: =Z27/$Z$4 -> 0.0017263577 | AC27: 69 | AD27: =AC27/$AC$4 -> 0.0023871303
M28: Basic EPS (€) | Q28: 7.41 | R28: =Q28/AC28-1 -> 0.28645833 | S28: =Q28/$Q$4 -> 0.00018454871 | T28: 7.61 | U28: =T28/AC28-1 -> 0.32118056 | V28: =T28/$T$4 -> 0.00019946007 | W28: 7.15 | X28: =W28/AC28-1 -> 0.24131944 | Y28: =W28/$W$4 -> 0.00019915325 | Z28: 6.23 | AA28: =Z28/AC28-1 -> 0.081597222 | AB28: =Z28/$Z$4 -> 0.00018229167 | AC28: 5.76 | AD28: =AC28/$AC$4 -> 0.00019927348
M29: Diluted EPS (€) | Q29: 7.33 | R29: =Q29/AC29-1 -> 0.29276896 | S29: =Q29/$Q$4 -> 0.00018255629 | T29: 7.53 | U29: =T29/AC29-1 -> 0.32804233 | V29: =T29/$T$4 -> 0.00019736325 | W29: 7.07 | X29: =W29/AC29-1 -> 0.24691358 | Y29: =W29/$W$4 -> 0.00019692496 | Z29: 6.15 | AA29: =Z29/AC29-1 -> 0.084656085 | AB29: =Z29/$Z$4 -> 0.00017995084 | AC29: 5.67 | AD29: =AC29/$AC$4 -> 0.00019615983
M31: INTERPRETATION

Sheet Balance Sheet
N1: Balance sheet | O1: Q1 - 2026 | P1: 2025 | S1: 2024 | V1: 2023 | Y1: 2022 | AB1: 2021 | AE1: INTERPRETATION
P2: (€m) | Q2: trend | R2: common-size | S2: (€m) | T2: trend | U2: common-size | V2: (€m) | W2: trend | X2: common-size | Y2: (€m) | Z2: trend | AA2: common-size | AB2: (€m) | AC2: common-size
N3: Intangible assets | P3: 31080 | Q3: =(P3-AB3)/AB3 -> -0.0041334231 | R3: =P3/$P$6 -> 0.76805219 | S3: 32561 | T3: =S3/AB3-1 -> 0.043320837 | U3: =S3/$S$12 -> 0.49377493 | V3: 30501 | W3: =V3/AB3-1 -> -0.022685764 | X3: =V3/$V$12 -> 0.5178526 | Y3: 31509 | Z3: =Y3/AB3-1 -> 0.0096126117 | AA3: =Y3/$Y$12 -> 0.53983347 | AB3: 31209 | AC3: =AB3/$AB$12 -> 0.57214879
N4: Property, plant and equipment | P4: 5481 | Q4: =(P4-AB4)/AB4 -> 0.43256665 | R4: =P4/$P$6 -> 0.13544704 | S4: 4884 | T4: =S4/AB4-1 -> 0.27652901 | U4: =S4/$S$12 -> 0.074063964 | V4: 4209 | W4: =V4/AB4-1 -> 0.10010455 | X4: =V4/$V$12 -> 0.071461315 | Y4: 3935 | Z4: =Y4/AB4-1 -> 0.028489284 | AA4: =Y4/$Y$12 -> 0.067417078 | AB4: 3826 | AC4: =AB4/$AB$12 -> 0.070141346
N5: Other non-current assets | P5: 3905 | Q5: =(P5-AB5)/AB5 -> -0.044765166 | R5: =P5/$P$6 -> 0.096500766 | S5: 4506 | T5: =S5/AB5-1 -> 0.10225049 | U5: =S5/$S$12 -> 0.068331741 | V5: 4087 | W5: =V5/AB5-1 -> -0.0002446184 | X5: =V5/$V$12 -> 0.069389973 | Y5: 3982 | Z5: =Y5/AB5-1 -> -0.02592955 | AA5: =Y5/$Y$12 -> 0.068222314 | AB5: 4088 | AC5: =AB5/$AB$12 -> 0.074944543
N6: Total non-current assets | P6: =P3+P4+P5 -> 40466 | Q6: =(P6-AB6)/AB6 -> 0.034327633 | R6: =P6/$P$12 -> 0.64741457 | S6: =S3+S4+S5 -> 41951 | T6: =S6/AB6-1 -> 0.072284845 | U6: =S6/$S$12 -> 0.63617063 | V6: =V3+V4+V5 -> 38797 | W6: =V6/AB6-1 -> -0.0083326943 | X6: =V6/$V$12 -> 0.65870388 | Y6: =Y3+Y4+Y5 -> 39426 | Z6: =Y6/AB6-1 -> 0.0077448048 | AA6: =Y6/$Y$12 -> 0.67547286 | AB6: =AB3+AB4+AB5 -> 39123 | AC6: =AB6/$AB$12 -> 0.71723468
N7: Inventories | P7: 5368 | Q7: =(P7-AB7)/AB7 -> 0.35180055 | R7: =P7/$P$11 -> 0.24357927 | S7: 5411 | T7: =S7/AB7-1 -> 0.36262906 | U7: =S7/$S$12 -> 0.082055715 | V7: 4519 | W7: =V7/AB7-1 -> 0.1380005 | X7: =V7/$V$12 -> 0.076724562 | Y7: 4346 | Z7: =Y7/AB7-1 -> 0.094434651 | AA7: =Y7/$Y$12 -> 0.074458607 | AB7: 3971 | AC7: =AB7/$AB$12 -> 0.072799604
N8: Accounts receivable | P8: 9836 | Q8: =(P8-AB8)/AB8 -> 0.44032801 | R8: =P8/$P$11 -> 0.44631999 | S8: 9364 | T8: =S8/AB8-1 -> 0.37121101 | U8: =S8/$S$12 -> 0.14200143 | V8: 8388 | W8: =V8/AB8-1 -> 0.22829111 | X8: =V8/$V$12 -> 0.14241328 | Y8: 7514 | Z8: =Y8/AB8-1 -> 0.10030751 | AA8: =Y8/$Y$12 -> 0.12873492 | AB8: 6829 | AC8: =AB8/$AB$12 -> 0.12519479
N9: Other current assets | P9: 2200 | Q9: =(P9-AB9)/AB9 -> 0.098901099 | R9: =P9/$P$11 -> 0.099827571 | S9: 2330 | T9: =S9/AB9-1 -> 0.16383616 | U9: =S9/$S$12 -> 0.035333546 | V9: 2290 | W9: =V9/AB9-1 -> 0.14385614 | X9: =V9/$V$12 -> 0.038880117 | Y9: 2155 | Z9: =Y9/AB9-1 -> 0.076423576 | AA9: =Y9/$Y$12 -> 0.036920916 | AB9: 2002 | AC9: =AB9/$AB$12 -> 0.036702293
N10: Cash and cash equivalents | P10: 4634 | Q10: =(P10-AB10)/AB10 -> 0.76735317 | R10: =P10/$P$11 -> 0.21027316 | S10: 6887 | T10: =S10/AB10-1 -> 1.6266209 | U10: =S10/$S$12 -> 0.10443868 | V10: 4696 | W10: =V10/AB10-1 -> 0.79099924 | X10: =V10/$V$12 -> 0.079729707 | Y10: 4927 | Z10: =Y10/AB10-1 -> 0.87909992 | AA10: =Y10/$Y$12 -> 0.084412692 | AB10: 2622 | AC10: =AB10/$AB$12 -> 0.048068638
N11: Total current assets | P11: =P7+P8+P9+P10 -> 22038 | Q11: =(P11-AB11)/AB11 -> 0.42881224 | R11: =P11/$P$12 -> 0.35258543 | S11: =S7+S8+S9+S10 -> 23992 | T11: =S11/AB11-1 -> 0.55549793 | U11: =S11/$S$12 -> 0.36382937 | V11: =V7+V8+V9+V10 -> 19893 | W11: =V11/AB11-1 -> 0.28974326 | X11: =V11/$V$12 -> 0.33774767 | Y11: =Y7+Y8+Y9+Y10 -> 18942 | Z11: =Y11/AB11-1 -> 0.2280861 | AA11: =Y11/$Y$12 -> 0.32452714 | AB11: =AB7+AB8+AB9+AB10 -> 15424 | AC11: =AB11/$AB$12 -> 0.28276532
N12: Total assets | P12: =P11+P6 -> 62504 | Q12: =(P12-AB12)/AB12 -> 0.1458742 | R12: =R11+R6 -> 1 | S12: =S11+S6 -> 65943 | T12: =S12/AB12-1 -> 0.20892075 | U12: =S12/$S$12 -> 1 | V12: =V11+V6+209 -> 58899 | W12: =V12/AB12-1 -> 0.079784406 | X12: =V12/$V$12 -> 1 | Y12: =Y11+Y6 -> 58368 | Z12: =Y12/AB12-1 -> 0.070049682 | AA12: =Y12/$Y$12 -> 1 | AB12: =AB11+AB6 -> 54547 | AC12: =AB12/$AB$12 -> 1
N13: Issued share capital | P13: 2308 | Q13: =(P13-AB13)/AB13 -> 0.014059754 | R13: =P13/$P$17 -> 0.094377428 | S13: 2303 | T13: =S13/AB13-1 -> 0.011862917 | U13: =S13/$S$12 -> 0.034924101 | V13: 2291 | W13: =V13/AB13-1 -> 0.0065905097 | X13: =V13/$V$12 -> 0.038897095 | Y13: 2284 | Z13: =Y13/AB13-1 -> 0.0035149385 | AA13: =Y13/$Y$12 -> 0.039131031 | AB13: 2276 | AC13: =AB13/$AB$12 -> 0.041725484
N14: Capital & Other reserves | P14: =(24159000+256000)/1000 -> 24415 | Q14: =(P14-AB14)/AB14 -> 2.9770321 | R14: =P14/$P$17 -> 0.99836434 | S14: 5300 | T14: =S14/AB14-1 -> -0.13666721 | U14: =S14/$S$12 -> 0.080372443 | V14: 3284 | W14: =V14/AB14-1 -> -0.46505946 | X14: =V14/$V$12 -> 0.055756464 | Y14: 3998 | Z14: =Y14/AB14-1 -> -0.34875387 | AA14: =Y14/$Y$12 -> 0.068496436 | AB14: 6139 | AC14: =AB14/$AB$12 -> 0.11254514
N15: Equity portion of convertible debt | P15: 0 | S15: 0 | V15: 0 | X15: =V15/$V$12 -> 0 | Y15: 0 | AB15: 0 | AC15: =AB15/$AB$12 -> 0
N16: Retained earnings | P16: -2268 | Q16: =(P16-AB16)/AB16 -> -1.115162 | R16: =P16/$P$17 -> -0.092741771 | S16: 23677 | T16: =S16/AB16-1 -> 0.20224434 | U16: =S16/$S$12 -> 0.35905252 | V16: 21593 | W16: =V16/AB16-1 -> 0.096425307 | X16: =V16/$V$12 -> 0.36661064 | Y16: 19812 | Z16: =Y16/AB16-1 -> 0.0059916726 | AA16: =Y16/$Y$12 -> 0.33943257 | AB16: 19694 | AC16: =AB16/$AB$12 -> 0.36104644
N17: Total equity | P17: =SUM(P13:P16) -> 24455 | Q17: =(P17-AB17)/AB17 -> -0.12999395 | R17: =P17/$P$26 -> 0.39125496 | S17: =SUM(S13:S16) -> 31280 | T17: =S17/AB17-1 -> 0.11281084 | U17: =S17/$S$12 -> 0.47434906 | V17: =SUM(V13:V16) -> 27168 | W17: =V17/AB17-1 -> -0.033476822 | X17: =V17/$V$12 -> 0.4612642 | Y17: =SUM(Y13:Y16) -> 26094 | Z17: =Y17/AB17-1 -> -0.071685225 | AA17: =Y17/$Y$12 -> 0.44706003 | AB17: =SUM(AB13:AB16) -> 28109 | AC17: =AB17/$AB$12 -> 0.51531707
N18: Borrowings & similar liabilities | P18: 15021 | Q18: =(P18-AB18)/AB18 -> 0.98848292 | R18: =P18/$P$20 -> 0.7686128 | S18: 10910 | T18: =S18/AB18-1 -> 0.44426794 | U18: =S18/$S$12 -> 0.16544592 | V18: 11592 | W18: =V18/AB18-1 -> 0.53455123 | X18: =V18/$V$12 -> 0.19681149 | Y18: 7330 | Z18: =Y18/AB18-1 -> -0.029653164 | AA18: =Y18/$Y$12 -> 0.12558251 | AB18: 7554 | AC18: =AB18/$AB$12 -> 0.13848608
N19: Other non-current liabilities | P19: 4522 | Q19: =(P19-AB19)/AB19 -> -0.03003003 | R19: =P19/$P$20 -> 0.2313872 | S19: 4184 | T19: =S19/AB19-1 -> -0.1025311 | U19: =S19/$S$12 -> 0.063448736 | V19: 3629 | W19: =V19/AB19-1 -> -0.22157872 | X19: =V19/$V$12 -> 0.061613949 | Y19: 4124 | Z19: =Y19/AB19-1 -> -0.11540112 | AA19: =Y19/$Y$12 -> 0.070655154 | AB19: 4662 | AC19: =AB19/$AB$12 -> 0.085467578
N20: Total non-current liabilities | P20: =SUM(P18:P19) -> 19543 | Q20: =(P20-AB20)/AB20 -> 0.59978716 | R20: =P20/$P$26 -> 0.31266799 | S20: =S18+S19 -> 15094 | T20: =S20/AB20-1 -> 0.23559267 | U20: =S20/$S$12 -> 0.22889465 | V20: =V18+V19 -> 15221 | W20: =V20/AB20-1 -> 0.24598887 | X20: =V20/$V$12 -> 0.25842544 | Y20: =Y18+Y19 -> 11454 | Z20: =Y20/AB20-1 -> -0.06237721 | AA20: =Y20/$Y$12 -> 0.19623766 | AB20: =AB18+AB19 -> 12216 | AC20: =AB20/$AB$12 -> 0.22395365
N21: Accounts payable | P21: 9327 | Q21: =(P21-AB21)/AB21 -> 0.632021 | R21: =P21/$P$25 -> 0.5039987 | S21: 8893 | T21: =S21/AB21-1 -> 0.55608049 | U21: =S21/$S$12 -> 0.13485889 | V21: 7596 | W21: =V21/AB21-1 -> 0.32913386 | X21: =V21/$V$12 -> 0.12896654 | Y21: 6254 | Z21: =Y21/AB21-1 -> 0.094313211 | AA21: =Y21/$Y$12 -> 0.10714775 | AB21: 5715 | AC21: =AB21/$AB$12 -> 0.10477203
N22: Bank overdraft | P22: 0 | S22: 0 | V22: 0 | Y22: 0 | AB22: 0 | AC22: =AB22/$AB$12 -> 0
N23: Borrowings & similar liabilities | P23: 2859 | Q23: =(P23-AB23)/AB23 -> 0.30250569 | R23: =P23/$P$25 -> 0.15449044 | S23: 3921 | T23: =S23/AB23-1 -> 0.78633257 | U23: =S23/$S$12 -> 0.059460443 | V23: 2341 | W23: =V23/AB23-1 -> 0.066514806 | X23: =V23/$V$12 -> 0.039746006 | Y23: 3133 | Z23: =Y23/AB23-1 -> 0.42733485 | AA23: =Y23/$Y$12 -> 0.053676672 | AB23: 2195 | AC23: =AB23/$AB$12 -> 0.040240527
N24: Other current liabilities | P24: 6320 | Q24: =(P24-AB24)/AB24 -> 0.0012674271 | R24: =P24/$P$25 -> 0.34151086 | S24: 6755 | T24: =S24/AB24-1 -> 0.070183777 | U24: =S24/$S$12 -> 0.10243695 | V24: 6573 | W24: =V24/AB24-1 -> 0.04134981 | X24: =V24/$V$12 -> 0.11159782 | Y24: 11433 | Z24: =Y24/AB24-1 -> 0.81131179 | AA24: =Y24/$Y$12 -> 0.19587788 | AB24: 6312 | AC24: =AB24/$AB$12 -> 0.11571672
N25: Total current liabilities | P25: =SUM(P21:P24) -> 18506 | Q25: =(P25-AB25)/AB25 -> 0.30122346 | R25: =P25/$P$26 -> 0.29607705 | S25: =SUM(S21:S24) -> 19569 | T25: =S25/AB25-1 -> 0.37596681 | U25: =S25/$S$12 -> 0.29675629 | V25: =SUM(V21:V24) -> 16510 | W25: =V25/AB25-1 -> 0.16087751 | X25: =V25/$V$12 -> 0.28031036 | Y25: =SUM(Y21:Y24) -> 20820 | Z25: =Y25/AB25-1 -> 0.46392912 | AA25: =Y25/$Y$12 -> 0.3567023 | AB25: =SUM(AB21:AB24) -> 14222 | AC25: =AB25/$AB$12 -> 0.26072928
N26: Total equity and liabilities | P26: =P25+P20+P17 -> 62504 | Q26: =(P26-AB26)/AB26 -> 0.1458742 | R26: =SUM(R17+R20+R25) -> 1 | S26: =S25+S20+S17 -> 65943 | T26: =S26/AB26-1 -> 0.20892075 | U26: =S26/$S$12 -> 1 | V26: =V25+V20+V17 -> 58899 | W26: =V26/AB26-1 -> 0.079784406 | X26: =V26/$V$12 -> 1 | Y26: =Y25+Y20+Y17 -> 58368 | Z26: =Y26/AB26-1 -> 0.070049682 | AA26: =Y26/$Y$12 -> 1 | AB26: =AB25+AB20+AB17 -> 54547 | AC26: =AB26/$AB$12 -> 1
H29: 1000 | R29: 2025 | S29: trend | T29: 2024 | U29: trend | V29: 2023 | W29: trend | X29: 2022 | Y29: trend | Z29: 2021
R30: =P4 -> 5481 | S30: =R30/Z30-1 -> 0.43256665 | T30: =S4 -> 4884 | U30: =T30/Z30-1 -> 0.27652901 | V30: =V4 -> 4209 | W30: =V30/Z30-1 -> 0.10010455 | X30: =Y4 -> 3935 | Y30: =X30/Z30-1 -> 0.028489284 | Z30: =AB4 -> 3826
R31: =P3 -> 31080 | S31: =R31/Z31-1 -> -0.0041334231 | T31: =S3 -> 32561 | U31: =T31/Z31-1 -> 0.043320837 | V31: =V3 -> 30501 | W31: =V31/Z31-1 -> -0.022685764 | X31: =Y3 -> 31509 | Y31: =X31/Z31-1 -> 0.0096126117 | Z31: =AB3 -> 31209
R32: =P5 -> 3905 | S32: =R32/Z32-1 -> -0.044765166 | T32: =S5 -> 4506 | U32: =T32/Z32-1 -> 0.10225049 | V32: =V5 -> 4087 | W32: =V32/Z32-1 -> -0.0002446184 | X32: =Y5 -> 3982 | Y32: =X32/Z32-1 -> -0.02592955 | Z32: =AB5 -> 4088
O33: FA | P33: A | R33: =SUM(R30:R32) -> 40466 | S33: =R33/Z33-1 -> 0.034327633 | T33: =SUM(T30:T32) -> 41951 | U33: =T33/Z33-1 -> 0.072284845 | V33: =SUM(V30:V32) -> 38797 | W33: =V33/Z33-1 -> -0.0083326943 | X33: =SUM(X30:X32) -> 39426 | Y33: =X33/Z33-1 -> 0.0077448048 | Z33: =SUM(Z30:Z32) -> 39123
O34: Inventories | R34: =P7 -> 5368 | S34: =R34/Z34-1 -> 0.35180055 | T34: =S7 -> 5411 | U34: =T34/Z34-1 -> 0.36262906 | V34: =V7 -> 4519 | W34: =V34/Z34-1 -> 0.1380005 | X34: =Y7 -> 4346 | Y34: =X34/Z34-1 -> 0.094434651 | Z34: =AB7 -> 3971
O35: Trade Receivables | R35: =P8+P9 -> 12036 | S35: =R35/Z35-1 -> 0.36292606 | T35: =S8+S9 -> 11694 | U35: =T35/Z35-1 -> 0.32419884 | V35: =V8+V9 -> 10678 | W35: =V35/Z35-1 -> 0.20914959 | X35: =Y8+Y9 -> 9669 | Y35: =X35/Z35-1 -> 0.094892991 | Z35: =AB8+AB9 -> 8831
O36: Trade Payables | R36: =P21+P24 -> 15647 | S36: =R36/Z36-1 -> 0.30098944 | T36: =S21+S24 -> 15648 | U36: =T36/Z36-1 -> 0.30107259 | V36: =V21+V24 -> 14169 | W36: =V36/Z36-1 -> 0.17809928 | X36: =Y21+Y24 -> 17687 | Y36: =X36/Z36-1 -> 0.4706078 | Z36: =AB21+AB24 -> 12027
O38: WCN | P38: B | R38: =R34+R35-R36 -> 1757 | S38: =R38/Z38-1 -> 1.2670968 | T38: =T34+T35-T36 -> 1457 | U38: =T38/Z38-1 -> 0.88 | V38: =V34+V35-V36 -> 1028 | W38: =V38/Z38-1 -> 0.32645161 | X38: =X34+X35-X36 -> -3672 | Y38: =X38/Z38-1 -> -5.7380645 | Z38: =Z34+Z35-Z36 -> 775
O40: Capital Employed | P40: A+B | R40: =R33+R38 -> 42223 | S40: =R40/Z40-1 -> 0.058273598 | T40: =T33+T38 -> 43408 | U40: =T40/Z40-1 -> 0.087974335 | V40: =V33+V38 -> 39825 | W40: =V40/Z40-1 -> -0.0018296656 | X40: =X33+X38 -> 35754 | Y40: =X40/Z40-1 -> -0.10386486 | Z40: =Z33+Z38 -> 39898
O41: Share Capital | R41: =P13 -> 2308 | S41: =R41/Z41-1 -> 0.014059754 | T41: =S13 -> 2303 | U41: =T41/Z41-1 -> 0.011862917 | V41: =V13 -> 2291 | W41: =V41/Z41-1 -> 0.0065905097 | X41: =Y13 -> 2284 | Y41: =X41/Z41-1 -> 0.0035149385 | Z41: =AB13 -> 2276
O42: Reserves | R42: =P14 -> 24415 | S42: =R42/Z42-1 -> 2.9770321 | T42: =S14 -> 5300 | U42: =T42/Z42-1 -> -0.13666721 | V42: =V14 -> 3284 | W42: =V42/Z42-1 -> -0.46505946 | X42: =Y14 -> 3998 | Y42: =X42/Z42-1 -> -0.34875387 | Z42: =AB14 -> 6139
O43: Retained Earnings | R43: =P16 -> -2268 | T43: =S16 -> 23677 | V43: =V16 -> 21593 | X43: =Y16 -> 19812 | Z43: =AB16 -> 19694
O44: SE | P44: C | R44: =R41+R42+R43 -> 24455 | S44: =R44/Z44-1 -> -0.12999395 | T44: =T41+T42+T43 -> 31280 | U44: =T44/Z44-1 -> 0.11281084 | V44: =V41+V42+V43 -> 27168 | W44: =V44/Z44-1 -> -0.033476822 | X44: =X41+X42+X43 -> 26094 | Y44: =X44/Z44-1 -> -0.071685225 | Z44: =Z41+Z42+Z43 -> 28109
...

Sheet Cash Flow Statement
P1: Line Item | Q1: FY2026(€m) | R1: Trennd | S1: FY2025 (€m) | T1: Trend | U1: FY2024 (€m) | V1: Trend | W1: FY2023 (€m) | X1: Trend | Y1: FY2022 (€m) | Z1: Trend | AA1: FY2021 (€m) | AC1: INTERPRETATION
P2: Net income | S2: 4351 | T2: =S2/AA2-1 -> 0.32936144 | U2: 4439 | V2: =U2/AA2-1 -> 0.35624809 | W2: 4169 | X2: =W2/AA2-1 -> 0.27375496 | Y2: 3536 | Z2: =Y2/AA2-1 -> 0.080354415 | AA2: 3273
P3: Share of profit of equity-accounted investments | S3: -14 | T3: =S3/AA3-1 -> -0.83333333 | U3: -17 | V3: =U3/AA3-1 -> -0.79761905 | W3: -51 | X3: =W3/AA3-1 -> -0.39285714 | Y3: -29 | Z3: =Y3/AA3-1 -> -0.6547619 | AA3: -84
P4: Impairment of investments in associates and joint ventures | S4: 388 | T4: =S4/U4-1 -> 0.76363636 | U4: 220
P5: Non-cash items: | U5: - | W5: 743 | X5: =W5/AA5-1 -> 0.023415978 | Y5: 750 | Z5: =Y5/AA5-1 -> 0.033057851 | AA5: 726
P6: Depreciation of property, plant and equipment | S6: 871 | T6: =S6/AA6-1 -> 0.26598837 | U6: 822 | V6: =U6/AA6-1 -> 0.19476744 | W6: 717 | X6: =W6/AA6-1 -> 0.042151163 | Y6: 732 | Z6: =Y6/AA6-1 -> 0.063953488 | AA6: 688
P7: Amortization of intangible assets | S7: 781 | T7: =S7/AA7-1 -> 21.970588 | U7: 716 | V7: =U7/AA7-1 -> 20.058824 | W7: 60 | X7: =W7/AA7-1 -> 0.76470588 | Y7: 61 | Z7: =Y7/AA7-1 -> 0.79411765 | AA7: 34
P8: Depreciation of non-current assets | S8: 53 | T8: =S8/AA8-1 -> -1.9814815 | U8: 31 | V8: =U8/AA8-1 -> -1.5740741 | W8: 87 | X8: =W8/AA8-1 -> -2.6111111 | Y8: 32 | Z8: =Y8/AA8-1 -> -1.5925926 | AA8: -54
P9: Increase/(decrease) in provisions | S9: 106 | T9: =S9/AA9-1 -> -1.576087 | U9: 93 | V9: =U9/AA9-1 -> -1.5054348 | W9: -252 | X9: =W9/AA9-1 -> 0.36956522 | Y9: 70 | Z9: =Y9/AA9-1 -> -1.3804348 | AA9: -184
P10: Gains/(losses) on disposals of activities and fixed assets | S10: -25 | T10: =S10/AA10-1 -> -0.34210526 | U10: -115 | V10: =U10/AA10-1 -> 2.0263158 | W10: -164 | X10: =W10/AA10-1 -> 3.3157895 | Y10: 139 | Z10: =Y10/AA10-1 -> -4.6578947 | AA10: -38
P11: Income tax expense | S11: 1455 | T11: =S11/U11-1 -> 0.040772532 | U11: 1398
P12: Other non-cash items | S12: 200 | T12: =S12/AA12-1 -> 0.85185185 | U12: 200 | V12: =U12/AA12-1 -> 0.85185185 | W12: 220 | X12: =W12/AA12-1 -> 1.037037 | Y12: 102 | Z12: =Y12/AA12-1 -> -0.055555556 | AA12: 108
P13: Income taxes paid, net | S13: -1418 | T13: =S13/U13-1 -> -0.041244084 | U13: -1479
P14: Operating cash flow | S14: 6748 | T14: =S14/AA14-1 -> 0.50995748 | U14: 6308 | V14: =U14/AA14-1 -> 0.41150145 | W14: 5529 | X14: =W14/AA14-1 -> 0.23718953 | Y14: 5393 | Z14: =Y14/AA14-1 -> 0.20675766 | AA14: 4469
P15: Decrease/(increase) in trade receivables | S15: -301 | T15: =S15/AA15-1 -> -0.47833622 | U15: -199 | V15: =U15/AA15-1 -> -0.65511265 | W15: 62 | X15: =W15/AA15-1 -> -1.1074523 | Y15: -305 | Z15: =Y15/AA15-1 -> -0.47140381 | AA15: -577
P16: Decrease/(increase) in inventories | S16: -366 | T16: =S16/AA16-1 -> -0.61675393 | U16: -834 | V16: =U16/AA16-1 -> -0.12670157 | W16: -382 | X16: =W16/AA16-1 -> -0.6 | Y16: -553 | Z16: =Y16/AA16-1 -> -0.42094241 | AA16: -955
P17: (Decrease)/increase in trade payables | S17: 307 | T17: =S17/AA17-1 -> -0.26555024 | U17: 439 | V17: =U17/AA17-1 -> 0.050239234 | W17: 493 | X17: =W17/AA17-1 -> 0.17942584 | Y17: 73 | Z17: =Y17/AA17-1 -> -0.82535885 | AA17: 418
P18: Decrease/(increase) in other current assets and liabilities | S18: -257 | T18: =S18/AA18-1 -> -1.9846743 | U18: -134 | V18: =U18/AA18-1 -> -1.51341 | W18: 205 | X18: =W18/AA18-1 -> -0.21455939 | Y18: -254 | Z18: =Y18/AA18-1 -> -1.9731801 | AA18: 261
P19: Change in working capital | S19: -617 | T19: =S19/AA19-1 -> -0.27667057 | U19: -728 | V19: =U19/AA19-1 -> -0.14654162 | W19: 378 | X19: =W19/AA19-1 -> -1.4431419 | Y19: -1039 | Z19: =Y19/AA19-1 -> 0.21805393 | AA19: -853
P20: TOTAL I - CASH FROM / (USED IN) OPERATING ACTIVITIES | S20: 6131 | T20: =S20/AA20-1 -> 0.69551991 | U20: 5580 | V20: =U20/AA20-1 -> 0.54314159 | W20: 5907 | X20: =W20/AA20-1 -> 0.63357301 | Y20: 4354 | Z20: =Y20/AA20-1 -> 0.20409292 | AA20: 3616
P21: Acquisitions of property, plant and equipment | S21: -1072 | T21: =S21/AA21-1 -> 0.97421731 | U21: -950 | V21: =U21/AA21-1 -> 0.74953959 | W21: -914 | X21: =W21/AA21-1 -> 0.68324125 | Y21: -707 | Z21: =Y21/AA21-1 -> 0.30202578 | AA21: -543
P22: Acquisitions of intangible assets | S22: -471 | T22: =S22/AA22-1 -> 0.41441441 | U22: -469 | V22: =U22/AA22-1 -> 0.40840841 | W22: -451 | X22: =W22/AA22-1 -> 0.35435435 | Y22: -386 | Z22: =Y22/AA22-1 -> 0.15915916 | AA22: -333
P23: Disposals of property, plant and equipment and intangibles | S23: 47 | T23: =S23/AA23-1 -> -0.20338983 | U23: 55 | V23: =U23/AA23-1 -> -0.06779661 | W23: 52 | X23: =W23/AA23-1 -> -0.11864407 | Y23: 69 | Z23: =Y23/AA23-1 -> 0.16949153 | AA23: 59
P24: Net capital expenditure | S24: -1496 | T24: =S24/AA24-1 -> 0.83108935 | U24: -1364 | V24: =U24/AA24-1 -> 0.66952264 | W24: -1313 | X24: =W24/AA24-1 -> 0.60709914 | Y24: -1024 | Z24: =Y24/AA24-1 -> 0.25336597 | AA24: -817
P25: Acquisitions and disposals of activities, net of cash acquired and divested | S25: -1158 | T25: =S25/AA25-1 -> -0.72630584 | U25: -452 | V25: =U25/AA25-1 -> -0.89316946 | W25: 611 | X25: =W25/AA25-1 -> -1.1444103 | Y25: -297 | Z25: =Y25/AA25-1 -> -0.92980383 | AA25: -4231
... P29: TOTAL II - CASH FROM / (USED IN) INVESTING ACTIVITIES | S29: -2717 | T29: =S29/AA29-1 -> -0.47426471 | U29: -1987 | V29: =U29/AA29-1 -> -0.61551858 | W29: -1048 | X29: =W29/AA29-1 -> -0.79721362 | Y29: -1411 | Z29: =Y29/AA29-1 -> -0.72697368 | AA29: -5168
P30: Issuance of bonds | S30: 4864 | T30: =S30/U30-1 -> 0.4033468 | U30: 3466 | V30: =U30/W30-1 -> -0.012254203 | W30: 3509 | X30: =W30/Y30-1 -> 2.21337 | Y30: 1092 | AA30: -
P31: Repayment of bonds | S31: -1800 | T31: =S31/AA31-1 -> 2 | U31: -1384 | V31: =U31/AA31-1 -> 1.3066667 | W31: -1299 | X31: =W31/AA31-1 -> 1.165 | Y31: -829 | Z31: =Y31/AA31-1 -> 0.38166667 | AA31: -600
P32: Purchase/(sale) of treasury shares | S32: -341 | T32: =S32/AA32-1 -> 0.30152672 | U32: -322 | V32: =U32/AA32-1 -> 0.22900763 | W32: -703 | X32: =W32/AA32-1 -> 1.6832061 | Y32: -219 | Z32: =Y32/AA32-1 -> -0.16412214 | AA32: -262
P33: Increase/(decrease) in other financial liabilities and other debt | S33: -510 | T33: =S33/AA33-1 -> 0.14864865 | U33: -1338 | V33: =U33/AA33-1 -> 2.0135135 | W33: 939 | X33: =W33/AA33-1 -> -3.1148649 | Y33: 143 | Z33: =Y33/AA33-1 -> -1.3220721 | AA33: -444
P34: Issuance and repurchase of OCEANEs (equity component) | S34: 109 | T34: =S34/U34-1 -> -2.6515152 | U34: -66 | W34: - | Y34: - | AA34: -
P35: Increase/(reduction) of share capital in cash | S35: 271 | T35: =S35/AA35-1 -> 0.25462963 | U35: 252 | V35: =U35/AA35-1 -> 0.16666667 | W35: 284 | X35: =W35/AA35-1 -> 0.31481481 | Y35: 208 | Z35: =Y35/AA35-1 -> -0.037037037 | AA35: 216
P36: Transactions with non-controlling interests | S36: -5535 | T36: =S36/AA36-1 -> 12.241627 | U36: -183 | V36: =U36/AA36-1 -> -0.56220096 | W36: -4702 | X36: =W36/AA36-1 -> 10.248804 | Y36: -73 | Z36: =Y36/AA36-1 -> -0.82535885 | AA36: -418
P37: Dividends paid to Schneider Electric shareholders | S37: -2191 | T37: =S37/AA37-1 -> 0.51416724 | U37: -1963 | V37: =U37/AA37-1 -> 0.35659986 | W37: -1767 | X37: =W37/AA37-1 -> 0.2211472 | Y37: -1618 | Z37: =Y37/AA37-1 -> 0.11817554 | AA37: -1447
P38: Dividends paid to minority shareholders | S38: -96 | T38: =S38/AA38-1 -> -0.30434783 | U38: -86 | V38: =U38/AA38-1 -> -0.37681159 | W38: -84 | X38: =W38/AA38-1 -> -0.39130435 | Y38: -157 | Z38: =Y38/AA38-1 -> 0.13768116 | AA38: -138
P39: TOTAL III - CASH FROM / (USED IN) FINANCING ACTIVITIES | S39: -5229 | T39: =S39/AA39-1 -> 0.69059166 | U39: -1624 | V39: =U39/AA39-1 -> -0.47494342 | W39: -3823 | X39: =W39/AA39-1 -> 0.23601681 | Y39: -1453 | Z39: =Y39/AA39-1 -> -0.53022955 | AA39: -3093
P40: TOTAL IV - NET EFFECT OF EXCHANGE RATES | S40: -410 | T40: =S40/AA40-1 -> -2.1849711 | U40: 189 | V40: =U40/AA40-1 -> -0.45375723 | W40: -240 | X40: =W40/AA40-1 -> -1.6936416 | Y40: -70 | Z40: =Y40/AA40-1 -> -1.2023121 | AA40: 346
P41: TOTAL V - IMPACT OF ASSETS HELD FOR SALE | S41: - | U41: - | W41: -4 | X41: =W41/Y41-1 -> -0.8 | Y41: -20 | AA41: -
P42: NET CHANGE IN CASH: I + II + III + IV + V | S42: -2225 | T42: =S42/AA42-1 -> -0.48243778 | U42: 2158 | V42: =U42/AA42-1 -> -1.5019772 | W42: 792 | X42: =W42/AA42-1 -> -1.1842289 | Y42: 1400 | Z42: =Y42/AA42-1 -> -1.3256571 | AA42: -4299
P43: Opening net cash | S43: 6812 | T43: =S43/AA43-1 -> 0.0073942621 | U43: 4654 | V43: =U43/AA43-1 -> -0.31174209 | W43: 3863 | X43: =W43/AA43-1 -> -0.42871931 | Y43: 2463 | Z43: =Y43/AA43-1 -> -0.63575865 | AA43: 6762
...

Sheet Ratios
D1: RATIO ANALYSIS | E1: Q1 2026 | F1: 2025 | G1: 2024 | H1: 2023 | I1: 2022 | J1: 2021 | L1: Balance Sheet | M1: Q1 2026 ($m) | N1: FY2025 (€m) | O1: FY2024 (€m) | P1: FY2023 (€m) | Q1: FY2022 (€m) | R1: FY2021 (€m) | U1: INTERPRETATION
L2: ='Balance Sheet'!N3 -> Intangible assets | M2: ='Balance Sheet'!O3 -> 0 | N2: ='Balance Sheet'!P3 -> 31080 | O2: ='Balance Sheet'!S3 -> 32561 | P2: ='Balance Sheet'!V3 -> 30501 | Q2: ='Balance Sheet'!Y3 -> 31509 | R2: ='Balance Sheet'!AB3 -> 31209
D3: Profitability analysis | L3: ='Balance Sheet'!N4 -> Property, plant and equipment | M3: ='Balance Sheet'!O4 -> 0 | N3: ='Balance Sheet'!P4 -> 5481 | O3: ='Balance Sheet'!S4 -> 4884 | P3: ='Balance Sheet'!V4 -> 4209 | Q3: ='Balance Sheet'!Y4 -> 3935 | R3: ='Balance Sheet'!AB4 -> 3826
D4: ROE | E4: =M49/M16 -> #DIV/0! | F4: =N49/N16 -> 0.17791863 | G4: =O49/O16 -> 0.14191176 | H4: =P49/P16 -> 0.15345259 | I4: =Q49/Q16 -> 0.13551008 | J4: =R49/R16 -> 0.11643957 | L4: ='Balance Sheet'!N5 -> Other non-current assets | M4: ='Balance Sheet'!O5 -> 0 | N4: ='Balance Sheet'!P5 -> 3905 | O4: ='Balance Sheet'!S5 -> 4506 | P4: ='Balance Sheet'!V5 -> 4087 | Q4: ='Balance Sheet'!Y5 -> 3982 | R4: ='Balance Sheet'!AB5 -> 4088
D5: ROS | E5: =M49/M28 -> #DIV/0! | F5: =N49/N28 -> 0.10836322 | G5: =O49/O28 -> 0.11634734 | H5: =P49/P28 -> 0.11612166 | I5: =Q49/Q28 -> 0.10346442 | J5: =R49/R28 -> 0.113233 | L5: ='Balance Sheet'!N6 -> Total non-current assets | M5: ='Balance Sheet'!O6 -> 0 | N5: ='Balance Sheet'!P6 -> 40466 | O5: ='Balance Sheet'!S6 -> 41951 | P5: ='Balance Sheet'!V6 -> 38797 | Q5: ='Balance Sheet'!Y6 -> 39426 | R5: ='Balance Sheet'!AB6 -> 39123
D6: Assets turnover | E6: =M28/M11 -> #DIV/0! | F6: =N28/N11 -> 0.64239089 | G6: =O28/O11 -> 0.57857544 | H6: =P28/P11 -> 0.60955194 | I6: =Q28/Q11 -> 0.58552632 | J6: =R28/R11 -> 0.52990999 | L6: ='Balance Sheet'!N7 -> Inventories | M6: ='Balance Sheet'!O7 -> 0 | N6: ='Balance Sheet'!P7 -> 5368 | O6: ='Balance Sheet'!S7 -> 5411 | P6: ='Balance Sheet'!V7 -> 4519 | Q6: ='Balance Sheet'!Y7 -> 4346 | R6: ='Balance Sheet'!AB7 -> 3971
D7: Equity Multiplier | E7: =M11/M16 -> #DIV/0! | F7: =N11/N16 -> 2.5558781 | G7: =O11/O16 -> 2.1081522 | H7: =P11/P16 -> 2.1679549 | I7: =Q11/Q16 -> 2.2368361 | J7: =R11/R16 -> 1.9405528 | L7: ='Balance Sheet'!N8 -> Accounts receivable | M7: ='Balance Sheet'!O8 -> 0 | N7: ='Balance Sheet'!P8 -> 9836 | O7: ='Balance Sheet'!S8 -> 9364 | P7: ='Balance Sheet'!V8 -> 8388 | Q7: ='Balance Sheet'!Y8 -> 7514 | R7: ='Balance Sheet'!AB8 -> 6829
D8: ROE decomposition: Traditional approach | L8: ='Balance Sheet'!N9 -> Other current assets | M8: ='Balance Sheet'!O9 -> 0 | N8: ='Balance Sheet'!P9 -> 2200 | O8: ='Balance Sheet'!S9 -> 2330 | P8: ='Balance Sheet'!V9 -> 2290 | Q8: ='Balance Sheet'!Y9 -> 2155 | R8: ='Balance Sheet'!AB9 -> 2002
D9: ROE = ROS x Assets turnover x Eq. Multiplier | E9: =E5*E6*E7 -> #DIV/0! | F9: =F5*F6*F7 -> 0.17791863 | G9: =G5*G6*G7 -> 0.14191176 | H9: =H5*H6*H7 -> 0.15345259 | I9: =I5*I6*I7 -> 0.13551008 | J9: =J5*J6*J7 -> 0.11643957 | L9: ='Balance Sheet'!N10 -> Cash and cash equivalents | M9: ='Balance Sheet'!O10 -> 0 | N9: ='Balance Sheet'!P10 -> 4634 | O9: ='Balance Sheet'!S10 -> 6887 | P9: ='Balance Sheet'!V10 -> 4696 | Q9: ='Balance Sheet'!Y10 -> 4927 | R9: ='Balance Sheet'!AB10 -> 2622
D10: Operating management: Profit margins | L10: ='Balance Sheet'!N11 -> Total current assets | M10: ='Balance Sheet'!O11 -> 0 | N10: ='Balance Sheet'!P11 -> 22038 | O10: ='Balance Sheet'!S11 -> 23992 | P10: ='Balance Sheet'!V11 -> 19893 | Q10: ='Balance Sheet'!Y11 -> 18942 | R10: ='Balance Sheet'!AB11 -> 15424
D11: Gross profit margin | E11: =M30/M28 -> #DIV/0! | F11: =N30/N28 -> 0.42077605 | G11: =O30/O28 -> 0.42638849 | H11: =P30/P28 -> 0.41813827 | I11: =Q30/Q28 -> 0.40601592 | J11: =R30/R28 -> 0.4097215 | L11: ='Balance Sheet'!N12 -> Total assets | M11: ='Balance Sheet'!O12 -> 0 | N11: ='Balance Sheet'!P12 -> 62504 | O11: ='Balance Sheet'!S12 -> 65943 | P11: ='Balance Sheet'!V12 -> 58899 | Q11: ='Balance Sheet'!Y12 -> 58368 | R11: ='Balance Sheet'!AB12 -> 54547
D12: EBITA (in £m/€m) | E12: =M36 -> 0 | F12: =N36 -> 7156 | G12: =O36 -> 6855 | H12: =P36 -> 6363 | I12: =Q36 -> 5357 | J12: =R36 -> 4741 | L12: ='Balance Sheet'!N13 -> Issued share capital | M12: ='Balance Sheet'!O13 -> 0 | N12: ='Balance Sheet'!P13 -> 2308 | O12: ='Balance Sheet'!S13 -> 2303 | P12: ='Balance Sheet'!V13 -> 2291 | Q12: ='Balance Sheet'!Y13 -> 2284 | R12: ='Balance Sheet'!AB13 -> 2276
D13: EBITDA (in £m/€m) | E13: =M37 -> #VALUE! | F13: =N37 -> 8027 | G13: =O37 -> 7677 | H13: =P37 -> 7080 | I13: =Q37 -> 6089 | J13: =R37 -> 5429 | L13: ='Balance Sheet'!N14 -> Capital & Other reserves | M13: ='Balance Sheet'!O14 -> 0 | N13: ='Balance Sheet'!P14 -> 24415 | O13: ='Balance Sheet'!S14 -> 5300 | P13: ='Balance Sheet'!V14 -> 3284 | Q13: ='Balance Sheet'!Y14 -> 3998 | R13: ='Balance Sheet'!AB14 -> 6139
D14: EBITA margin | E14: =M36/M28 -> #DIV/0! | F14: =N36/N28 -> 0.17822275 | G14: =O36/O28 -> 0.17967132 | H14: =P36/P28 -> 0.17723247 | I14: =Q36/Q28 -> 0.15674743 | J14: =R36/R28 -> 0.16402007 | L14: ='Balance Sheet'!N15 -> Equity portion of convertible debt | M14: ='Balance Sheet'!O15 -> 0 | N14: ='Balance Sheet'!P15 -> 0 | O14: ='Balance Sheet'!S15 -> 0 | P14: ='Balance Sheet'!V15 -> 0 | Q14: ='Balance Sheet'!Y15 -> 0 | R14: ='Balance Sheet'!AB15 -> 0
D15: EBITDA margin | E15: =M37/M28 -> #VALUE! | F15: =N37/N28 -> 0.19991532 | G15: =O37/O28 -> 0.20121616 | H15: =P37/P28 -> 0.1972035 | I15: =Q37/Q28 -> 0.17816596 | J15: =R37/R28 -> 0.18782218 | L15: ='Balance Sheet'!N16 -> Retained earnings | M15: ='Balance Sheet'!O16 -> 0 | N15: ='Balance Sheet'!P16 -> -2268 | O15: ='Balance Sheet'!S16 -> 23677 | P15: ='Balance Sheet'!V16 -> 21593 | Q15: ='Balance Sheet'!Y16 -> 19812 | R15: ='Balance Sheet'!AB16 -> 19694
D16: Operating profit (or EBIT) margin | E16: =M39/M28 -> #DIV/0! | F16: =N39/N28 -> 0.166841 | G16: =O39/O28 -> 0.16902996 | H16: =P39/P28 -> 0.16525542 | I16: =Q39/Q28 -> 0.14434106 | J16: =R39/R28 -> 0.14983567 | L16: ='Balance Sheet'!N17 -> Total equity | M16: ='Balance Sheet'!O17 -> 0 | N16: ='Balance Sheet'!P17 -> 24455 | O16: ='Balance Sheet'!S17 -> 31280 | P16: ='Balance Sheet'!V17 -> 27168 | Q16: ='Balance Sheet'!Y17 -> 26094 | R16: ='Balance Sheet'!AB17 -> 28109
D17: Investment management: Working capital management | L17: ='Balance Sheet'!N18 -> Borrowings & similar liabilities | M17: ='Balance Sheet'!O18 -> 0 | N17: ='Balance Sheet'!P18 -> 15021 | O17: ='Balance Sheet'!S18 -> 10910 | P17: ='Balance Sheet'!V18 -> 11592 | Q17: ='Balance Sheet'!Y18 -> 7330 | R17: ='Balance Sheet'!AB18 -> 7554
D18: Days' receivables | E18: =(M7*360)/M28 -> #DIV/0! | F18: =(N7*360)/N28 -> 88.188882 | G18: =(O7*360)/O28 -> 88.35583 | H18: =(P7*360)/P28 -> 84.108963 | I18: =(Q7*360)/Q28 -> 79.150281 | J18: =(R7*360)/R28 -> 85.052413 | L18: ='Balance Sheet'!N19 -> Other non-current liabilities | M18: ='Balance Sheet'!O19 -> 0 | N18: ='Balance Sheet'!P19 -> 4522 | O18: ='Balance Sheet'!S19 -> 4184 | P18: ='Balance Sheet'!V19 -> 3629 | Q18: ='Balance Sheet'!Y19 -> 4124 | R18: ='Balance Sheet'!AB19 -> 4662
D19: Days' inventories | E19: =(M6*360)/M29 -> #DIV/0! | F19: =(N6*360)/-N29 -> 83.092402 | G19: =(O6*360)/-O29 -> 89.00891 | H19: =(P6*360)/-P29 -> 77.876496 | I19: =(Q6*360)/-Q29 -> 77.071921 | J19: =(R6*360)/-R29 -> 83.786192 | L19: ='Balance Sheet'!N20 -> Total non-current liabilities | M19: ='Balance Sheet'!O20 -> 0 | N19: ='Balance Sheet'!P20 -> 19543 | O19: ='Balance Sheet'!S20 -> 15094 | P19: ='Balance Sheet'!V20 -> 15221 | Q19: ='Balance Sheet'!Y20 -> 11454 | R19: ='Balance Sheet'!AB20 -> 12216
D20: Days' payables | E20: =(M20*360)/-M29 -> #DIV/0! | F20: =(N20*360)/-N29 -> 144.3746 | G20: =(O20*360)/-O29 -> 146.2865 | H20: =(P20*360)/-P29 -> 130.90282 | I20: =(Q20*360)/-Q29 -> 110.90837 | J20: =(R20*360)/-R29 -> 120.58375 | L20: ='Balance Sheet'!N21 -> Accounts payable | M20: ='Balance Sheet'!O21 -> 0 | N20: ='Balance Sheet'!P21 -> 9327 | O20: ='Balance Sheet'!S21 -> 8893 | P20: ='Balance Sheet'!V21 -> 7596 | Q20: ='Balance Sheet'!Y21 -> 6254 | R20: ='Balance Sheet'!AB21 -> 5715
D21: CCC | E21: =E18+E19-E20 -> #DIV/0! | F21: =F18+F19-F20 -> 26.906688 | G21: =G18+G19-G20 -> 31.078243 | H21: =H18+H19-H20 -> 31.082635 | I21: =I18+I19-I20 -> 45.313828 | J21: =J18+J19-J20 -> 48.254851 | L21: ='Balance Sheet'!N22 -> Bank overdraft | M21: ='Balance Sheet'!O22 -> 0 | N21: ='Balance Sheet'!P22 -> 0 | O21: ='Balance Sheet'!S22 -> 0 | P21: ='Balance Sheet'!V22 -> 0 | Q21: ='Balance Sheet'!Y22 -> 0 | R21: ='Balance Sheet'!AB22 -> 0
D22: Investment management: Non-current asset management | L22: ='Balance Sheet'!N23 -> Borrowings & similar liabilities | M22: ='Balance Sheet'!O23 -> 0 | N22: ='Balance Sheet'!P23 -> 2859 | O22: ='Balance Sheet'!S23 -> 3921 | P22: ='Balance Sheet'!V23 -> 2341 | Q22: ='Balance Sheet'!Y23 -> 3133 | R22: ='Balance Sheet'!AB23 -> 2195
D23: PP&E turnover | E23: =M28/M3 -> #DIV/0! | F23: =N28/N3 -> 7.3256705 | G23: =O28/O3 -> 7.8118346 | H23: =P28/P3 -> 8.5298171 | I23: =Q28/Q3 -> 8.6851334 | J23: =R28/R3 -> 7.5548876 | L23: ='Balance Sheet'!N24 -> Other current liabilities | M23: ='Balance Sheet'!O24 -> 0 | N23: ='Balance Sheet'!P24 -> 6320 | O23: ='Balance Sheet'!S24 -> 6755 | P23: ='Balance Sheet'!V24 -> 6573 | Q23: ='Balance Sheet'!Y24 -> 11433 | R23: ='Balance Sheet'!AB24 -> 6312
D24: Financial management: Liquidity analysis | L24: ='Balance Sheet'!N25 -> Total current liabilities | M24: ='Balance Sheet'!O25 -> 0 | N24: ='Balance Sheet'!P25 -> 18506 | O24: ='Balance Sheet'!S25 -> 19569 | P24: ='Balance Sheet'!V25 -> 16510 | Q24: ='Balance Sheet'!Y25 -> 20820 | R24: ='Balance Sheet'!AB25 -> 14222
D25: Current ratio | E25: =M10/M24 -> #DIV/0! | F25: =N10/N24 -> 1.190857 | G25: =O10/O24 -> 1.2260207 | H25: =P10/P24 -> 1.2049061 | I25: =Q10/Q24 -> 0.90979827 | J25: =R10/R24 -> 1.0845169 | L25: ='Balance Sheet'!N26 -> Total equity and liabilities | M25: ='Balance Sheet'!O26 -> 0 | N25: ='Balance Sheet'!P26 -> 62504 | O25: ='Balance Sheet'!S26 -> 65943 | P25: ='Balance Sheet'!V26 -> 58899 | Q25: ='Balance Sheet'!Y26 -> 58368 | R25: ='Balance Sheet'!AB26 -> 54547
D26: Quick ratio | E26: =(M10-M6)/M24 -> #DIV/0! | F26: =(N10-N6)/N24 -> 0.90078893 | G26: =(O10-O6)/O24 -> 0.94951198 | H26: =(P10-P6)/P24 -> 0.93119322 | I26: =(Q10-Q6)/Q24 -> 0.70105668 | J26: =(R10-R6)/R24 -> 0.80530165
D27: Cash ratio | E27: =M9/M24 -> #DIV/0! | F27: =N9/N24 -> 0.25040527 | G27: =O9/O24 -> 0.35193418 | H27: =P9/P24 -> 0.28443368 | I27: =Q9/Q24 -> 0.23664745 | J27: =R9/R24 -> 0.18436226 | L27: Income Statement | M27: Q1 2026 (€m) | N27: FY2025 (€m) | O27: FY2024 (€m) | P27: FY2023 (€m) | Q27: FY2022 (€m) | R27: FY2021 (€m)
D28: Financial management: Solvency analysis | L28: Revenue | M28: ='Income Statement'!N4 -> 0 | N28: ='Income Statement'!Q4 -> 40152 | O28: ='Income Statement'!T4 -> 38153 | P28: ='Income Statement'!W4 -> 35902 | Q28: ='Income Statement'!Z4 -> 34176 | R28: ='Income Statement'!AC4 -> 28905
D29: Debt to equity | E29: =(M17+M22)/M16 -> #DIV/0! | F29: =(N17+N22)/N16 -> 0.73113883 | G29: =(O17+O22)/O16 -> 0.47413683 | H29: =(P17+P22)/P16 -> 0.512846 | I29: =(Q17+Q22)/Q16 -> 0.4009734 | J29: =(R17+R22)/R16 -> 0.34682842 | L29: Cost of sales | M29: ='Income Statement'!N5 -> 0 | N29: ='Income Statement'!Q5 -> -23257 | O29: ='Income Statement'!T5 -> -21885 | P29: ='Income Statement'!W5 -> -20890 | Q29: ='Income Statement'!Z5 -> -20300 | R29: ='Income Statement'!AC5 -> -17062
D30: Total debt ratio | E30: =(M17+M22)/M11 -> #DIV/0! | F30: =(N17+N22)/N11 -> 0.28606169 | G30: =(O17+O22)/O11 -> 0.22490636 | H30: =(P17+P22)/P11 -> 0.2365575 | I30: =(Q17+Q22)/Q11 -> 0.17925918 | J30: =(R17+R22)/R11 -> 0.1787266 | L30: Gross profit | M30: ='Income Statement'!N6 -> 0 | N30: ='Income Statement'!Q6 -> 16895 | O30: ='Income Statement'!T6 -> 16268 | P30: ='Income Statement'!W6 -> 15012 | Q30: ='Income Statement'!Z6 -> 13876 | R30: ='Income Statement'!AC6 -> 11843
D31: Interest coverage | E31: =M39/ABS(M41) -> #DIV/0! | F31: =N39/ABS(N41) -> 14.162791 | G31: =O39/ABS(O41) -> 14.825287 | H31: =P39/ABS(P41) -> 15.330749 | I31: =Q39/ABS(Q41) -> 37.946154 | J31: =R39/ABS(R41) -> 43.747475 | L31: Research and development | M31: ='Income Statement'!N7 -> 0 | N31: ='Income Statement'!Q7 -> -1365 | O31: ='Income Statement'!T7 -> -1308 | P31: ='Income Statement'!W7 -> -1168 | Q31: ='Income Statement'!Z7 -> -1040 | R31: ='Income Statement'!AC7 -> -855
D32: Net Debt-to-EBITA | E32: =(M19+M21-M9)/M36 -> #DIV/0! | F32: =(N19+N21-N9)/N36 -> 2.0834265 | G32: =(O19+O21-O9)/O36 -> 1.1972283 | H32: =(P19+P21-P9)/P36 -> 1.654094 | I32: =(Q19+Q21-Q9)/Q36 -> 1.2184058 | J32: =(R19+R21-R9)/R36 -> 2.0236237 | L32: Selling, general and administrative expenses | M32: ='Income Statement'!N8 -> 0 | N32: ='Income Statement'!Q8 -> -8010 | O32: ='Income Statement'!T8 -> -7877 | P32: ='Income Statement'!W8 -> -7432 | Q32: ='Income Statement'!Z8 -> -6819 | R32: ='Income Statement'!AC8 -> -6001
D33: Net Debt-to-EBITDA | E33: =(M19+M21-M9)/M37 -> #VALUE! | F33: =(N19+N21-N9)/N37 -> 1.8573564 | G33: =(O19+O21-O9)/O37 -> 1.0690374 | H33: =(P19+P21-P9)/P37 -> 1.4865819 | I33: =(Q19+Q21-Q9)/Q37 -> 1.071933 | J33: =(R19+R21-R9)/R37 -> 1.7671763 | L33: Adjusted EBITA | M33: ='Income Statement'!N9 -> 0 | N33: ='Income Statement'!Q9 -> 7520 | O33: ='Income Statement'!T9 -> 7083 | P33: ='Income Statement'!W9 -> 6412 | Q33: ='Income Statement'!Z9 -> 6017 | R33: ='Income Statement'!AC9 -> 4987
D34: Ratio for investors/shareholders | L34: Other operating income and expenses | M34: ='Income Statement'!N10 -> 0 | N34: ='Income Statement'!Q10 -> -77 | O34: ='Income Statement'!T10 -> -87 | P34: ='Income Statement'!W10 -> 98 | Q34: ='Income Statement'!Z10 -> -433 | R34: ='Income Statement'!AC10 -> -21
D35: Dividend payout ratio | E35: =E47/M50 -> #DIV/0! | F35: =F47/N50 -> 0.52630315 | G35: =G47/O50 -> 0.45982666 | H35: =H47/P50 -> 0.44141894 | I35: =I47/Q50 -> 0.46534369 | J35: =J47/R50 -> 0.45162297 | L35: Restructuring charges | M35: ='Income Statement'!N11 -> 0 | N35: ='Income Statement'!Q11 -> -287 | O35: ='Income Statement'!T11 -> -141 | P35: ='Income Statement'!W11 -> -147 | Q35: ='Income Statement'!Z11 -> -227 | R35: ='Income Statement'!AC11 -> -225
D36: Dividend yield | E36: =E47/E45/E46 -> #DIV/0! | F36: =F47/F45/F46 -> 0.016602411 | G36: =G47/G45/G46 -> 0.014525865 | H36: =H47/H45/H46 -> 0.017362446 | I36: =I47/I45/I46 -> 0.02217787 | J36: =J47/J45/J46 -> 0.015083778 | L36: EBITA | M36: ='Income Statement'!N12 -> 0 | N36: ='Income Statement'!Q12 -> 7156 | O36: ='Income Statement'!T12 -> 6855 | P36: ='Income Statement'!W12 -> 6363 | Q36: ='Income Statement'!Z12 -> 5357 | R36: ='Income Statement'!AC12 -> 4741
D37: Earnings per share | E37: =M50/E45 -> #DIV/0! | F37: =N50/F45 -> 7.41 | G37: =O50/G45 -> 7.61 | H37: =P50/H45 -> 7.15 | I37: =Q50/I45 -> 6.23 | J37: =R50/J45 -> 5.76 | L37: EBITDA (restated) | M37: ='Income Statement'!N13 -> #VALUE! | N37: ='Income Statement'!Q13 -> 8027 | O37: ='Income Statement'!T13 -> 7677 | P37: ='Income Statement'!W13 -> 7080 | Q37: ='Income Statement'!Z13 -> 6089 | R37: ='Income Statement'!AC13 -> 5429
D38: P/E ratio | E38: =E46/E37 -> #DIV/0! | F38: =F46/F37 -> 31.700405 | G38: =G46/G37 -> 31.655716 | H38: =H46/H37 -> 25.423776 | I38: =I46/I37 -> 20.982343 | J38: =J46/J37 -> 29.940972 | L38: Amortization of acquisition-related intangibles | M38: ='Income Statement'!N14 -> 0 | N38: ='Income Statement'!Q14 -> -457 | O38: ='Income Statement'!T14 -> -406 | P38: ='Income Statement'!W14 -> -430 | Q38: ='Income Statement'!Z14 -> -424 | R38: ='Income Statement'!AC14 -> -410
D39: P/B ratio | E39: =(E45*E46)/M16 -> #DIV/0! | F39: =(F45*F46)/N16 -> 5.3963928 | G39: =(G45*G46)/O16 -> 4.3202766 | H39: =(H45*H46)/P16 -> 3.7460018 | I39: =(I45*I46)/Q16 -> 2.7958768 | J39: =(J45*J46)/R16 -> 3.4128171 | L39: Operating income (EBIT) | M39: ='Income Statement'!N15 -> 0 | N39: ='Income Statement'!Q15 -> 6699 | O39: ='Income Statement'!T15 -> 6449 | P39: ='Income Statement'!W15 -> 5933 | Q39: ='Income Statement'!Z15 -> 4933 | R39: ='Income Statement'!AC15 -> 4331
D40: Net Debt | E40: =(M19+M21-M9) -> 0 | F40: =(N19+N21-N9) -> 14909 | G40: =(O19+O21-O9) -> 8207 | H40: =(P19+P21-P9) -> 10525 | I40: =(Q19+Q21-Q9) -> 6527 | J40: =(R19+R21-R9) -> 9594 | L40: Income from cash and cash equivalents | M40: ='Income Statement'!N16 -> 0 | N40: ='Income Statement'!Q16 -> 152 | O40: ='Income Statement'!T16 -> 174 | P40: ='Income Statement'!W16 -> 79 | Q40: ='Income Statement'!Z16 -> 24 | R40: ='Income Statement'!AC16 -> 4
...

Sheet Final Financial Analysis
B2: SCHNEIDER ELECTRIC SE
B3: Financial Analysis & Strategic Recommendations | FY2021–FY2025
B4: EXECUTIVE SUMMARY
B5: Over the 2021–2025 period, Schneider Electric delivered consistent and profitable growth: revenue rose from €28.9bn to €40.2bn (+39%), the EBITA margin expanded from 16.4% to 17.8%, and net income grew from €3.3bn to €4.4bn. Cash generation is one of the group's strongest assets; operating cash flow reached €6.1bn in 2025, up nearly 70% over five years, and dividends were increased every single year. The balance sheet remains broadly healthy, though leverage increased significantly in 2025 following strategic acquisitions (AVEVA, SEIPL), with Net Debt/EBITDA reaching 1.86x, the highest level of the period and the main financial risk to monitor going forward. Two structural weaknesses also stand out: working capital needs grew more than three times faster than revenue (+127% vs +39%), and R&D spending at ~3.4% of sales remains low for a group positioning itself as a technology company. Overall, Schneider is a financially solid, growing business, well-positioned on high-potential markets (electrification, data centres, AI infrastructure); the priority now is to reduce debt, step up innovation investment, and tighten working capital discipline to lock in long-term value creation.
B8: PART I — OVERALL FINANCIAL ANALYSIS
B10: 1. A MILESTONE YEAR: BREAKING THE €40 BILLION THRESHOLD
B12: FY2025 marks a historic milestone: Schneider Electric crossed the €40 billion revenue threshold for the first time, delivering +9% organic growth in a volatile macro environment. This performance is not circumstantial, it reflects five years of consistent execution across two structural megatrends: electrification and digitalization. Energy Management achieved double-digit organic growth for the fifth consecutive year, while Industrial Automation, which had struggled through a destocking cycle in 2024, returned to growth in 2025. The record backlog of over €25 billion, up +18% year-on-year, gives the group exceptional visibility heading into 2026 and beyond.
B13: 2. PROFITABILITY: ROBUST MARGINS DESPITE A COMPLEX ENVIRONMENT
B15: Schneider’s profitability has steadily improved over the period. The adjusted EBITA margin expanded to 17.8% in 2025, up from 16.4% in 2021, supported by a gross margin consistently holding around 42%, a sign of genuine pricing power and a richer product mix. Return on Equity reached 17.8%, the highest level in five years. The one nuance worth flagging: net margin experienced a slight compression in 2025, driven not by operational weakness but by the cost of a deliberate leverage increase to fund strategic acquisitions. This is a trade-off the Board consciously accepted, and one that must now be carefully managed.
B16: 3. THE DIGITAL FLYWHEEL: SCHNEIDER’S STRATEGIC TRANSFORMATION ENGINE
B18: The ‘Digital Flywheel’, Schneider’s integrated offer of connected products, software and services — is now the group’s primary growth engine, generating €25 billion in revenue and representing 62% of total sales. The full acquisition of AVEVA in 2023 was the pivotal move underpinning this transformation, giving Schneider a world-class industrial software platform used by over 20,000 customers. More recently, the acquisition of Motivair in late 2024, a specialist in liquid cooling for AI infrastructure, directly positions Schneider at the heart of the hyperscaler buildout. The joint launch of AI-Ready Data Center Reference Designs with NVIDIA in October 2025 confirmed Schneider’s ambition to become the infrastructure partner for the AI era. The target is clear: digital and recurring revenues to exceed 70% of group sales by 2030.
B19: 4. GOVERNANCE EVENT: THE CEO TRANSITION OF NOVEMBER 2024
... B71: The structural gap in R&D versus technology peers is not just a strategic concern, it is a valuation risk. If Schneider is perceived as primarily a hardware company with a software overlay, it will trade at industrial multiples rather than technology multiples. The pace of AI development makes this risk more acute: new entrants could commoditize elements of AVEVA’s platform faster than anticipated. The Board must treat R&D investment as a non-negotiable line item, not a variable cost.
